Workbook
Name CompanyList: Company_Requirements!$A$2:$A$11
Name Slicer_Degree: #N/A
Name Slicer_Placement_Status: #N/A
Name Slicer_Specialization: #N/A

Sheet Analysis
A1: Campus Placement Analysis
A3: Total Students | B3: =COUNTA(Eligibility_Engine!A8:A1000) -> 480
A4: Eligible Students | B4: =COUNTIF(Eligibility_Engine!F8:F1000,"Eligible") -> 84
A5: Not Eligible Students | B5: =COUNTIF(Eligibility_Engine!F8:F1000,"Not Eligible") -> 396
A6: Eligibility % | B6: =B4/B3 -> 0.175
A8: Selected Company | B8: =Eligibility_Engine!B3 -> Deloitte

Sheet Dashboard
A2: Campus Placement Intelligence Dashboard | H2: Student Search
H4: Enter Student ID | I4: STU0011
A5: Selected Company | B5: =Analysis!B8 -> Deloitte | D5: Status | E5: Count
D6: Eligible | E6: =B9 -> 84 | H6: Student Name | I6: =VLOOKUP(I4,Student_Master!A:M,2,FALSE) -> Ishita Desai
A7: Total Students | B7: =Analysis!B3 -> 480 | D7: Not Eligible | E7: =B11 -> 396 | H7: Degree | I7: =VLOOKUP(I4,Student_Master!A:M,3,FALSE) -> MCA
H8: CGPA | I8: =VLOOKUP(I4,Student_Master!A:M,5,FALSE) -> 8.86
A9: Eligible Students | B9: =Analysis!B4 -> 84 | H9: Backlogs | I9: =VLOOKUP(I4,Student_Master!A:M,8,FALSE) -> 0
D10: Metric | E10: Value | H10: Skills | I10: =VLOOKUP(I4,Student_Master!A:M,9,FALSE) -> Data Analysis, JavaScript, Java, Power BI
A11: Not Eligible Students | B11: =Analysis!B5 -> 396 | D11: Total Students | E11: =B7 -> 480 | H11: Eligibility | I11: =VLOOKUP(I4,Eligibility_Engine!A:G,6,FALSE) -> Eligible
D12: Eligible | E12: =B9 -> 84 | H12: Reason | I12: =VLOOKUP(I4,Eligibility_Engine!A:G,7,FALSE) -> Eligible
A13: Eligibility % | B13: =Analysis!B6 -> 0.175 | D13: Not Eligible | E13: =B11 -> 396
D14: Eligibility % | E14: =B13 -> 0.175

Sheet Student_Master
A1: Student_ID | B1: Student_Name | C1: Degree | D1: Specialization | E1: CGPA | F1: 10th_Percentage | G1: 12th_Percentage | H1: Active_Backlogs | I1: Skills | J1: Graduation_Year | K1: Placement_Status | L1: Company_Placed | M1: Package_LPA | N1: Overall_Rank | O1: Placement_Chance
A2: STU0001 | B2: Aarav Mishra | C2: MCA | D2: Computer Applications | E2: 8.77 | F2: 65.3 | G2: 56.4 | H2: 0 | I2: Git, JavaScript | J2: 2025 | K2: Placed | L2: Accenture | M2: 8.7 | N2: =RANK(E2,$E$2:$E$481,0) -> 112 | O2: =IF(E2>=9,"Very High",IF(E2>=8,"High",IF(E2>=7,"Medium","Low"))) -> High
A3: STU0002 | B3: Akash Desai | C3: BCA | D3: Web Technology | E3: 8.4 | F3: 77.9 | G3: 60.1 | H3: 0 | I3: Python, JavaScript | J3: 2026 | K3: Placed | L3: SAP Labs | M3: 6.8 | N3: =RANK(E3,$E$2:$E$481,0) -> 156 | O3: =IF(E3>=9,"Very High",IF(E3>=8,"High",IF(E3>=7,"Medium","Low"))) -> High
A4: STU0003 | B4: Neha Singh | C4: MCA | D4: Data Science | E4: 9.19 | F4: 80.4 | G4: 87.1 | H4: 0 | I4: JavaScript, SQL | J4: 2026 | K4: In Process | N4: =RANK(E4,$E$2:$E$481,0) -> 65 | O4: =IF(E4>=9,"Very High",IF(E4>=8,"High",IF(E4>=7,"Medium","Low"))) -> Very High
A5: STU0004 | B5: Kavya Singh | C5: BCA | D5: Web Technology | E5: 6.08 | F5: 82.8 | G5: 85.6 | H5: 3 | I5: SQL, JavaScript, Power BI | J5: 2026 | K5: Not Placed | N5: =RANK(E5,$E$2:$E$481,0) -> 445 | O5: =IF(E5>=9,"Very High",IF(E5>=8,"High",IF(E5>=7,"Medium","Low"))) -> Low
A6: STU0005 | B6: Rahul Gupta | C6: BCA | D6: Web Technology | E6: 6.87 | F6: 94.3 | G6: 79.8 | H6: 0 | I6: Data Analysis, Java, Python | J6: 2026 | K6: Placed | L6: Mindtree | M6: 10.1 | N6: =RANK(E6,$E$2:$E$481,0) -> 351 | O6: =IF(E6>=9,"Very High",IF(E6>=8,"High",IF(E6>=7,"Medium","Low"))) -> Low
A7: STU0006 | B7: Nikhil Shetty | C7: B.Tech | D7: Computer Science | E7: 6.72 | F7: 56.3 | G7: 64.5 | H7: 0 | I7: Git, HTML/CSS, Java | J7: 2026 | K7: In Process | N7: =RANK(E7,$E$2:$E$481,0) -> 371 | O7: =IF(E7>=9,"Very High",IF(E7>=8,"High",IF(E7>=7,"Medium","Low"))) -> Low
A8: STU0007 | B8: Bhavana Bhat | C8: B.Tech | D8: Information Science | E8: 6.79 | F8: 78.6 | G8: 62.1 | H8: 0 | I8: HTML/CSS, Java, Python, Power BI, Data Analysis | J8: 2025 | K8: Placed | L8: TCS | M8: 4.9 | N8: =RANK(E8,$E$2:$E$481,0) -> 364 | O8: =IF(E8>=9,"Very High",IF(E8>=8,"High",IF(E8>=7,"Medium","Low"))) -> Low
A9: STU0008 | B9: Ananya Hegde | C9: MCA | D9: Data Science | E9: 7.33 | F9: 96.8 | G9: 74.3 | H9: 2 | I9: SQL, Data Analysis | J9: 2026 | K9: Not Placed | N9: =RANK(E9,$E$2:$E$481,0) -> 297 | O9: =IF(E9>=9,"Very High",IF(E9>=8,"High",IF(E9>=7,"Medium","Low"))) -> Medium
A10: STU0009 | B10: Arjun Singh | C10: B.E | D10: Computer Science | E10: 7.61 | F10: 95.1 | G10: 90.3 | H10: 0 | I10: Data Analysis, SQL, Power BI | J10: 2026 | K10: Not Placed | N10: =RANK(E10,$E$2:$E$481,0) -> 257 | O10: =IF(E10>=9,"Very High",IF(E10>=8,"High",IF(E10>=7,"Medium","Low"))) -> Medium
A11: STU0010 | B11: Akash Gowda | C11: BCA | D11: Web Technology | E11: 9.61 | F11: 93.7 | G11: 92.3 | H11: 0 | I11: Excel, SQL, HTML/CSS, JavaScript, Python | J11: 2026 | K11: Placed | L11: IBM | M11: 13.4 | N11: =RANK(E11,$E$2:$E$481,0) -> 19 | O11: =IF(E11>=9,"Very High",IF(E11>=8,"High",IF(E11>=7,"Medium","Low"))) -> Very High
A12: STU0011 | B12: Ishita Desai | C12: MCA | D12: Cloud Computing | E12: 8.86 | F12: 60.4 | G12: 71.9 | H12: 0 | I12: Data Analysis, JavaScript, Java, Power BI | J12: 2026 | K12: In Process | N12: =RANK(E12,$E$2:$E$481,0) -> 93 | O12: =IF(E12>=9,"Very High",IF(E12>=8,"High",IF(E12>=7,"Medium","Low"))) -> High
A13: STU0012 | B13: Aditi Gupta | C13: B.Tech | D13: Data Science | E13: 9.4 | F13: 74 | G13: 61.4 | H13: 0 | I13: Git, Data Analysis | J13: 2026 | K13: Placed | L13: TCS | M13: 10.8 | N13: =RANK(E13,$E$2:$E$481,0) -> 39 | O13: =IF(E13>=9,"Very High",IF(E13>=8,"High",IF(E13>=7,"Medium","Low"))) -> Very High
A14: STU0013 | B14: Ananya Bhat | C14: MCA | D14: Computer Applications | E14: 9.24 | F14: 58 | G14: 60.9 | H14: 0 | I14: Data Analysis, Python, React | J14: 2026 | K14: Placed | L14: Deloitte | M14: 5.3 | N14: =RANK(E14,$E$2:$E$481,0) -> 54 | O14: =IF(E14>=9,"Very High",IF(E14>=8,"High",IF(E14>=7,"Medium","Low"))) -> Very High
A15: STU0014 | B15: Divya Nair | C15: B.Tech | D15: Data Science | E15: 7.44 | F15: 91.3 | G15: 52.5 | H15: 0 | I15: Excel, JavaScript | J15: 2026 | K15: Not Placed | N15: =RANK(E15,$E$2:$E$481,0) -> 285 | O15: =IF(E15>=9,"Very High",IF(E15>=8,"High",IF(E15>=7,"Medium","Low"))) -> Medium
A16: STU0015 | B16: Vikas Sharma | C16: BCA | D16: Web Technology | E16: 7.59 | F16: 72.7 | G16: 62.8 | H16: 0 | I16: React, Data Analysis | J16: 2025 | K16: In Process | N16: =RANK(E16,$E$2:$E$481,0) -> 262 | O16: =IF(E16>=9,"Very High",IF(E16>=8,"High",IF(E16>=7,"Medium","Low"))) -> Medium
A17: STU0016 | B17: Ishita Bhat | C17: MCA | D17: Computer Applications | E17: 6.47 | F17: 75.4 | G17: 59.8 | H17: 0 | I17: Python, JavaScript | J17: 2025 | K17: Not Placed | N17: =RANK(E17,$E$2:$E$481,0) -> 410 | O17: =IF(E17>=9,"Very High",IF(E17>=8,"High",IF(E17>=7,"Medium","Low"))) -> Low
A18: STU0017 | B18: Bhavana Patil | C18: B.E | D18: Computer Science | E18: 6.56 | F18: 64.1 | G18: 52.7 | H18: 0 | I18: HTML/CSS, Excel | J18: 2025 | K18: In Process | N18: =RANK(E18,$E$2:$E$481,0) -> 394 | O18: =IF(E18>=9,"Very High",IF(E18>=8,"High",IF(E18>=7,"Medium","Low"))) -> Low
A19: STU0018 | B19: Karan Joshi | C19: MCA | D19: Computer Applications | E19: 6.07 | F19: 57.9 | G19: 89.6 | H19: 0 | I19: Git, Excel, SQL | J19: 2026 | K19: In Process | N19: =RANK(E19,$E$2:$E$481,0) -> 447 | O19: =IF(E19>=9,"Very High",IF(E19>=8,"High",IF(E19>=7,"Medium","Low"))) -> Low
A20: STU0019 | B20: Akash Mishra | C20: BCA | D20: Web Technology | E20: 8.66 | F20: 65 | G20: 68.2 | H20: 0 | I20: React, HTML/CSS, SQL, Excel | J20: 2026 | K20: Not Placed | N20: =RANK(E20,$E$2:$E$481,0) -> 128 | O20: =IF(E20>=9,"Very High",IF(E20>=8,"High",IF(E20>=7,"Medium","Low"))) -> High
A21: STU0020 | B21: Pooja Sharma | C21: BCA | D21: Web Technology | E21: 6.86 | F21: 94.2 | G21: 90.5 | H21: 1 | I21: Power BI, Python, React, JavaScript | J21: 2026 | K21: In Process | N21: =RANK(E21,$E$2:$E$481,0) -> 353 | O21: =IF(E21>=9,"Very High",IF(E21>=8,"High",IF(E21>=7,"Medium","Low"))) -> Low
A22: STU0021 | B22: Pooja Gowda | C22: B.Tech | D22: Computer Science | E22: 9.56 | F22: 60.6 | G22: 55.3 | H22: 0 | I22: Power BI, Git, Java | J22: 2026 | K22: Placed | L22: Oracle | M22: 12.4 | N22: =RANK(E22,$E$2:$E$481,0) -> 26 | O22: =IF(E22>=9,"Very High",IF(E22>=8,"High",IF(E22>=7,"Medium","Low"))) -> Very High
A23: STU0022 | B23: Ananya Reddy | C23: B.Tech | D23: Computer Science | E23: 6.17 | F23: 72.8 | G23: 62.7 | H23: 0 | I23: Power BI, Python, React | J23: 2026 | K23: Not Placed | N23: =RANK(E23,$E$2:$E$481,0) -> 435 | O23: =IF(E23>=9,"Very High",IF(E23>=8,"High",IF(E23>=7,"Medium","Low"))) -> Low
A24: STU0023 | B24: Neha Singh | C24: BCA | D24: Web Technology | E24: 5.94 | F24: 70.5 | G24: 75.4 | H24: 0 | I24: Power BI, HTML/CSS | J24: 2027 | K24: Not Placed | N24: =RANK(E24,$E$2:$E$481,0) -> 467 | O24: =IF(E24>=9,"Very High",IF(E24>=8,"High",IF(E24>=7,"Medium","Low"))) -> Low
A25: STU0024 | B25: Aarav Kulkarni | C25: BCA | D25: Web Technology | E25: 6.8 | F25: 59.3 | G25: 85.9 | H25: 1 | I25: Git; Python; Java; JavaScript; SQL | J25: 2027 | K25: Not Placed | N25: =RANK(E25,$E$2:$E$481,0) -> 362 | O25: =IF(E25>=9,"Very High",IF(E25>=8,"High",IF(E25>=7,"Medium","Low"))) -> Low
A26: STU0025 | B26: Kavya Hegde | C26: B.Tech | D26: DATA SCIENCE | E26: 9.01 | F26: 91.3 | G26: 87.3 | H26: 0 | I26: JavaScript, Excel | J26: 2027 | K26: Placed | L26: Zoho | M26: 13.1 | N26: =RANK(E26,$E$2:$E$481,0) -> 85 | O26: =IF(E26>=9,"Very High",IF(E26>=8,"High",IF(E26>=7,"Medium","Low"))) -> Very High
A27: STU0026 | B27: Ananya Joshi | C27: BCA | D27: Computer Applications | E27: 5.89 | F27: 63.1 | G27: 65.1 | H27: 1 | I27: HTML/CSS, Data Analysis, JavaScript, Git | J27: 2027 | K27: Not Placed | N27: =RANK(E27,$E$2:$E$481,0) -> 471 | O27: =IF(E27>=9,"Very High",IF(E27>=8,"High",IF(E27>=7,"Medium","Low"))) -> Low
A28: STU0027 | B28: Aarav Verma | C28: BCA | D28: Web Technology | E28: 9.65 | F28: 66.1 | G28: 55 | H28: 0 | I28: JavaScript, Data Analysis, SQL, Java | J28: 2027 | K28: Placed | L28: Infosys | M28: 10.9 | N28: =RANK(E28,$E$2:$E$481,0) -> 14 | O28: =IF(E28>=9,"Very High",IF(E28>=8,"High",IF(E28>=7,"Medium","Low"))) -> Very High
A29: STU0028 | B29: Rahul Shetty | C29: BCA | D29: Data Analytics | E29: 7.53 | F29: 94.9 | G29: 92.4 | H29: 0 | I29: Power BI, Data Analysis | J29: 2026 | K29: Placed | L29: Deloitte | M29: 10.7 | N29: =RANK(E29,$E$2:$E$481,0) -> 272 | O29: =IF(E29>=9,"Very High",IF(E29>=8,"High",IF(E29>=7,"Medium","Low"))) -> Medium
A30: STU0029 | B30: Karan Naik | C30: BCA | D30: Data Analytics | E30: 8.46 | F30: 70.9 | G30: 84.4 | H30: 0 | I30: JavaScript, Data Analysis, Excel, Python | J30: 2026 | K30: Placed | L30: IBM | M30: 9.8 | N30: =RANK(E30,$E$2:$E$481,0) -> 148 | O30: =IF(E30>=9,"Very High",IF(E30>=8,"High",IF(E30>=7,"Medium","Low"))) -> High
A31: STU0030 | B31: Shreya Hegde | C31: B.E | D31: Information Science | E31: 8.5 | F31: 76.5 | G31: 86.5 | H31: 2 | I31: SQL, Power BI, HTML/CSS | J31: 2025 | K31: Not Placed | N31: =RANK(E31,$E$2:$E$481,0) -> 147 | O31: =IF(E31>=9,"Very High",IF(E31>=8,"High",IF(E31>=7,"Medium","Low"))) -> High
A32: STU0031 | B32: Sneha Desai | C32: BCA | D32: Computer Applications | E32: 6.39 | F32: 56.9 | G32: 95.3 | H32: 0 | I32: React, JavaScript | J32: 2027 | K32: In Process | N32: =RANK(E32,$E$2:$E$481,0) -> 417 | O32: =IF(E32>=9,"Very High",IF(E32>=8,"High",IF(E32>=7,"Medium","Low"))) -> Low
A33: STU0032 | B33: Nikhil Patil | C33: B.E | D33: Information Science | E33: 6.78 | F33: 82.6 | G33: 50.3 | H33: 0 | I33: JavaScript, Java | J33: 2026 | K33: In Process | N33: =RANK(E33,$E$2:$E$481,0) -> 366 | O33: =IF(E33>=9,"Very High",IF(E33>=8,"High",IF(E33>=7,"Medium","Low"))) -> Low
A34: STU0033 | B34: Suraj Gowda | C34: BCA | D34: Computer Applications | E34: 7.63 | F34: 88.7 | G34: 80.7 | H34: 3 | I34: React, Data Analysis, JavaScript, Git | J34: 2027 | K34: Not Placed | N34: =RANK(E34,$E$2:$E$481,0) -> 254 | O34: =IF(E34>=9,"Very High",IF(E34>=8,"High",IF(E34>=7,"Medium","Low"))) -> Medium
A35: STU0034 | B35: Akash Shetty | C35: B.E | D35: Information Science | E35: 8.81 | F35: 90.3 | G35: 62.8 | H35: 0 | I35: Java, Power BI, React, Excel, HTML/CSS | J35: 2026 | K35: Placed | L35: Capgemini | M35: 12.8 | N35: =RANK(E35,$E$2:$E$481,0) -> 105 | O35: =IF(E35>=9,"Very High",IF(E35>=8,"High",IF(E35>=7,"Medium","Low"))) -> High
A36: STU0035 | B36: Sneha Sharma | C36: BCA | D36: Computer Applications | E36: 7.33 | F36: 61.4 | G36: 59.8 | H36: 0 | I36: Data Analysis, React, JavaScript, Excel | J36: 2026 | K36: Placed | L36: Mindtree | M36: 11.5 | N36: =RANK(E36,$E$2:$E$481,0) -> 297 | O36: =IF(E36>=9,"Very High",IF(E36>=8,"High",IF(E36>=7,"Medium","Low"))) -> Medium
A37: STU0036 | B37: Karan Desai | C37: B.E | D37: Information Science | E37: 5.82 | F37: 69.8 | G37: 84.7 | H37: 1 | I37: Data Analysis, Git, Java, React, SQL | J37: 2026 | K37: Not Placed | N37: =RANK(E37,$E$2:$E$481,0) -> 475 | O37: =IF(E37>=9,"Very High",IF(E37>=8,"High",IF(E37>=7,"Medium","Low"))) -> Low
A38: STU0037 | B38: Harsh Desai | C38: BCA | D38: Data Analytics | E38: 9.48 | F38: 96.2 | G38: 74.6 | H38: 1 | I38: SQL, JavaScript | J38: 2025 | K38: Not Placed | N38: =RANK(E38,$E$2:$E$481,0) -> 33 | O38: =IF(E38>=9,"Very High",IF(E38>=8,"High",IF(E38>=7,"Medium","Low"))) -> Very High
A39: STU0038 | B39: Divya Reddy | C39: B.Tech | D39: Information Science | E39: 7.62 | F39: 69.2 | G39: 90.5 | H39: 0 | I39: Power BI, SQL, React, Excel, HTML/CSS | J39: 2026 | K39: Not Placed | N39: =RANK(E39,$E$2:$E$481,0) -> 255 | O39: =IF(E39>=9,"Very High",IF(E39>=8,"High",IF(E39>=7,"Medium","Low"))) -> Medium
A40: STU0039 | B40: Rohan Rao | C40: MCA | D40: Computer Applications | E40: 9.6 | F40: 63.4 | G40: 50.9 | H40: 0 | I40: React, SQL, Java | J40: 2026 | K40: Placed | L40: Capgemini | M40: 5 | N40: =RANK(E40,$E$2:$E$481,0) -> 21 | O40: =IF(E40>=9,"Very High",IF(E40>=8,"High",IF(E40>=7,"Medium","Low"))) -> Very High
...

Sheet Pivot_Analysis
A1: Placement Status Summary
A3: Placement Status | B3: Count of Student_ID
A4: In Process | B4: 31
A5: Not Placed | B5: 54
A6: Placed | B6: 53
A7: Grand Total | B7: 138
A18: Company-wise Placement Summary
A20: Companies | B20: Count of Student_ID
B21: 289
A22: Accenture | B22: 11
A23: Bosch | B23: 10
A24: Capgemini | B24: 18
A25: Cognizant | B25: 14
A26: Deloitte | B26: 13
A27: IBM | B27: 14
A28: Infosys | B28: 8
A29: LTIMindtree | B29: 8
A30: Mindtree | B30: 21
A31: Oracle | B31: 10
A32: SAP Labs | B32: 15
A33: TCS | B33: 11
... A37: Grand Total | B37: 480

Sheet Company_Requirements
A1: Company | B1: Min_CGPA | C1: Max_Backlogs | D1: Required_Skill | E1: Package_LPA | F1: Hiring_Status
A2: Infosys | B2: 6.5 | C2: 0 | D2: SQL | E2: 4.5 | F2: Open
A3: TCS | B3: 6 | C3: 1 | D3: Excel | E3: 4.2 | F3: Open
A4: Wipro | B4: 6.5 | C4: 0 | D4: Python | E4: 4.8 | F4: Open
A5: Accenture | B5: 7 | C5: 0 | D5: SQL | E5: 5.5 | F5: Open
A6: Cognizant | B6: 6.8 | C6: 0 | D6: Excel | E6: 5.2 | F6: Open
A7: Deloitte | B7: 7.5 | C7: 0 | D7: Power BI | E7: 7.2 | F7: Open
A8: Capgemini | B8: 6.5 | C8: 1 | D8: SQL | E8: 4.6 | F8: Open
A9: IBM | B9: 7.2 | C9: 0 | D9: Python | E9: 6.5 | F9: Open
A10: Oracle | B10: 7.5 | C10: 0 | D10: SQL | E10: 8 | F10: Open
A11: Zoho | B11: 7 | C11: 0 | D11: Java | E11: 6 | F11: Open

Sheet Eligibility_Engine
A1: Campus Placement Eligibility Engine
D2: Company Requirements
A3: Select Company | B3: Deloitte | D3: Minimum CGPA | E3: =VLOOKUP(B3,Company_Requirements!$A$2:$F$11,2,FALSE) -> 7.5
D4: Maximum Backlogs | E4: =VLOOKUP(B3,Company_Requirements!$A$2:$F$11,3,FALSE) -> 0
D5: Required Skill | E5: =VLOOKUP(B3,Company_Requirements!$A$2:$F$11,4,FALSE) -> Power BI
D6: Package (LPA) | E6: =VLOOKUP(B3,Company_Requirements!$A$2:$F$11,5,FALSE) -> 7.2
A7: Student_ID | B7: Student_Name | C7: CGPA | D7: Backlogs | E7: Skills | F7: Eligible | G7: Reason
A8: =Student_Master!A2 -> STU0001 | B8: =Student_Master!B2 -> Aarav Mishra | C8: =Student_Master!E2 -> 8.77 | D8: =Student_Master!H2 -> 0 | E8: =Student_Master!I2 -> Git, JavaScript | F8: =IF(AND(C8>=$E$3,D8<=$E$4,ISNUMBER(SEARCH($E$5,E8))),"Eligible","Not Eligible") -> Not Eligible | G8: =IF(C8<$E$3,"CGPA below requirement",IF(D8>$E$4,"Too many backlogs",IF(NOT(ISNUMBER(SEARCH($E$5,E8))),"Required skill missing","Eligible"))) -> Required skill missing
A9: =Student_Master!A3 -> STU0002 | B9: =Student_Master!B3 -> Akash Desai | C9: =Student_Master!E3 -> 8.4 | D9: =Student_Master!H3 -> 0 | E9: =Student_Master!I3 -> Python, JavaScript | F9: =IF(AND(C9>=$E$3,D9<=$E$4,ISNUMBER(SEARCH($E$5,E9))),"Eligible","Not Eligible") -> Not Eligible | G9: =IF(C9<$E$3,"CGPA below requirement",IF(D9>$E$4,"Too many backlogs",IF(NOT(ISNUMBER(SEARCH($E$5,E9))),"Required skill missing","Eligible"))) -> Required skill missing
A10: =Student_Master!A4 -> STU0003 | B10: =Student_Master!B4 -> Neha Singh | C10: =Student_Master!E4 -> 9.19 | D10: =Student_Master!H4 -> 0 | E10: =Student_Master!I4 -> JavaScript, SQL | F10: =IF(AND(C10>=$E$3,D10<=$E$4,ISNUMBER(SEARCH($E$5,E10))),"Eligible","Not Eligible") -> Not Eligible | G10: =IF(C10<$E$3,"CGPA below requirement",IF(D10>$E$4,"Too many backlogs",IF(NOT(ISNUMBER(SEARCH($E$5,E10))),"Required skill missing","Eligible"))) -> Required skill missing
A11: =Student_Master!A5 -> STU0004 | B11: =Student_Master!B5 -> Kavya Singh | C11: =Student_Master!E5 -> 6.08 | D11: =Student_Master!H5 -> 3 | E11: =Student_Master!I5 -> SQL, JavaScript, Power BI | F11: =IF(AND(C11>=$E$3,D11<=$E$4,ISNUMBER(SEARCH($E$5,E11))),"Eligible","Not Eligible") -> Not Eligible | G11: =IF(C11<$E$3,"CGPA below requirement",IF(D11>$E$4,"Too many backlogs",IF(NOT(ISNUMBER(SEARCH($E$5,E11))),"Required skill missing","Eligible"))) -> CGPA below requirement
A12: =Student_Master!A6 -> STU0005 | B12: =Student_Master!B6 -> Rahul Gupta | C12: =Student_Master!E6 -> 6.87 | D12: =Student_Master!H6 -> 0 | E12: =Student_Master!I6 -> Data Analysis, Java, Python | F12: =IF(AND(C12>=$E$3,D12<=$E$4,ISNUMBER(SEARCH($E$5,E12))),"Eligible","Not Eligible") -> Not Eligible | G12: =IF(C12<$E$3,"CGPA below requirement",IF(D12>$E$4,"Too many backlogs",IF(NOT(ISNUMBER(SEARCH($E$5,E12))),"Required skill missing","Eligible"))) -> CGPA below requirement
A13: =Student_Master!A7 -> STU0006 | B13: =Student_Master!B7 -> Nikhil Shetty | C13: =Student_Master!E7 -> 6.72 | D13: =Student_Master!H7 -> 0 | E13: =Student_Master!I7 -> Git, HTML/CSS, Java | F13: =IF(AND(C13>=$E$3,D13<=$E$4,ISNUMBER(SEARCH($E$5,E13))),"Eligible","Not Eligible") -> Not Eligible | G13: =IF(C13<$E$3,"CGPA below requirement",IF(D13>$E$4,"Too many backlogs",IF(NOT(ISNUMBER(SEARCH($E$5,E13))),"Required skill missing","Eligible"))) -> CGPA below requirement
A14: =Student_Master!A8 -> STU0007 | B14: =Student_Master!B8 -> Bhavana Bhat | C14: =Student_Master!E8 -> 6.79 | D14: =Student_Master!H8 -> 0 | E14: =Student_Master!I8 -> HTML/CSS, Java, Python, Power BI, Data Analysis | F14: =IF(AND(C14>=$E$3,D14<=$E$4,ISNUMBER(SEARCH($E$5,E14))),"Eligible","Not Eligible") -> Not Eligible | G14: =IF(C14<$E$3,"CGPA below requirement",IF(D14>$E$4,"Too many backlogs",IF(NOT(ISNUMBER(SEARCH($E$5,E14))),"Required skill missing","Eligible"))) -> CGPA below requirement
A15: =Student_Master!A9 -> STU0008 | B15: =Student_Master!B9 -> Ananya Hegde | C15: =Student_Master!E9 -> 7.33 | D15: =Student_Master!H9 -> 2 | E15: =Student_Master!I9 -> SQL, Data Analysis | F15: =IF(AND(C15>=$E$3,D15<=$E$4,ISNUMBER(SEARCH($E$5,E15))),"Eligible","Not Eligible") -> Not Eligible | G15: =IF(C15<$E$3,"CGPA below requirement",IF(D15>$E$4,"Too many backlogs",IF(NOT(ISNUMBER(SEARCH($E$5,E15))),"Required skill missing","Eligible"))) -> CGPA below requirement
A16: =Student_Master!A10 -> STU0009 | B16: =Student_Master!B10 -> Arjun Singh | C16: =Student_Master!E10 -> 7.61 | D16: =Student_Master!H10 -> 0 | E16: =Student_Master!I10 -> Data Analysis, SQL, Power BI | F16: =IF(AND(C16>=$E$3,D16<=$E$4,ISNUMBER(SEARCH($E$5,E16))),"Eligible","Not Eligible") -> Eligible | G16: =IF(C16<$E$3,"CGPA below requirement",IF(D16>$E$4,"Too many backlogs",IF(NOT(ISNUMBER(SEARCH($E$5,E16))),"Required skill missing","Eligible"))) -> Eligible
A17: =Student_Master!A11 -> STU0010 | B17: =Student_Master!B11 -> Akash Gowda | C17: =Student_Master!E11 -> 9.61 | D17: =Student_Master!H11 -> 0 | E17: =Student_Master!I11 -> Excel, SQL, HTML/CSS, JavaScript, Python | F17: =IF(AND(C17>=$E$3,D17<=$E$4,ISNUMBER(SEARCH($E$5,E17))),"Eligible","Not Eligible") -> Not Eligible | G17: =IF(C17<$E$3,"CGPA below requirement",IF(D17>$E$4,"Too many backlogs",IF(NOT(ISNUMBER(SEARCH($E$5,E17))),"Required skill missing","Eligible"))) -> Required skill missing
A18: =Student_Master!A12 -> STU0011 | B18: =Student_Master!B12 -> Ishita Desai | C18: =Student_Master!E12 -> 8.86 | D18: =Student_Master!H12 -> 0 | E18: =Student_Master!I12 -> Data Analysis, JavaScript, Java, Power BI | F18: =IF(AND(C18>=$E$3,D18<=$E$4,ISNUMBER(SEARCH($E$5,E18))),"Eligible","Not Eligible") -> Eligible | G18: =IF(C18<$E$3,"CGPA below requirement",IF(D18>$E$4,"Too many backlogs",IF(NOT(ISNUMBER(SEARCH($E$5,E18))),"Required skill missing","Eligible"))) -> Eligible
A19: =Student_Master!A13 -> STU0012 | B19: =Student_Master!B13 -> Aditi Gupta | C19: =Student_Master!E13 -> 9.4 | D19: =Student_Master!H13 -> 0 | E19: =Student_Master!I13 -> Git, Data Analysis | F19: =IF(AND(C19>=$E$3,D19<=$E$4,ISNUMBER(SEARCH($E$5,E19))),"Eligible","Not Eligible") -> Not Eligible | G19: =IF(C19<$E$3,"CGPA below requirement",IF(D19>$E$4,"Too many backlogs",IF(NOT(ISNUMBER(SEARCH($E$5,E19))),"Required skill missing","Eligible"))) -> Required skill missing
... A487: =Student_Master!A481 -> STU0480 | B487: =Student_Master!B481 -> Ishita Shetty | C487: =Student_Master!E481 -> 7.85 | D487: =Student_Master!H481 -> 0 | E487: =Student_Master!I481 -> React, Data Analysis, SQL | F487: =IF(AND(C487>=$E$3,D487<=$E$4,ISNUMBER(SEARCH($E$5,E487))),"Eligible","Not Eligible") -> Not Eligible | G487: =IF(C487<$E$3,"CGPA below requirement",IF(D487>$E$4,"Too many backlogs",IF(NOT(ISNUMBER(SEARCH($E$5,E487))),"Required skill missing","Eligible"))) -> Required skill missing
